Analysis of items.py for Specified Bugs
Bugs Identified (Strictly Matching Your Criteria):

    Code-breaking bug: Incorrect router initialization
        Issue: router = {} initializes router as a dictionary, but FastAPI expects an APIRouter object. This causes a runtime error when FastAPI tries to register routes, breaking the entire file.
        Type: Code-breaking bug
        Fix: Replace router = {} with router = APIRouter().
    Unnecessary code: Duplicate create_item endpoint
        Issue: Two @router.post("/") endpoints for create_item exist. The second one (return {"id": "Item Inserted"}) is unreachable because FastAPI uses the first endpoint, making it redundant and confusing.
        Type: Unnecessary code section
        Fix: Remove the second @router.post("/") endpoint.
    API call bug: Incorrect delete_item endpoint parameters
        Issue: The @router.delete("/{item_id}/{item_details}") endpoint expects item_details as a path parameter and attempts to delete an item using ObjectId(item_details). This is likely to cause a runtime error (InvalidId from bson) if item_details is not a valid ObjectId, as it’s unclear why a second ObjectId is needed. The dual deletion logic also violates REST conventions, making this an API design bug.
        Type: API call bug
        Fix: Remove the item_details parameter and second deletion, simplifying to delete only the item specified by item_id.
    Code-breaking bug: Incorrect response in delete_item
        Issue: The delete_item endpoint returns {"status": "deleted", "deleted_item": result2}, where result2 is the deletion result for item_details. This can break if result2 is not as expected (e.g., no deletion occurred), and it’s misleading because it doesn’t confirm the deletion of item_id. The check if result.deleted_count only verifies the first deletion, potentially returning an incorrect response.
        Type: Code-breaking bug
        Fix: Update the response to confirm deletion of item_id only, removing result2.

Logical bug: Incorrect response in delete_item

    Issue: The delete_item endpoint returns {"status": "deleted", "deleted_item": result2}, where result2 is the result of deleting an item by item_details. This is misleading because result2 may not correspond to the primary item deletion (item_id), and the response doesn’t confirm the deletion of item_id. Additionally, the if result.deleted_count check only verifies the first deletion, not both.
    Fix: If both deletions are intentional, check both result and result2 and return a clear response:
    python

    if result.deleted_count or result2.deleted_count:
        return {"status": "deleted", "deleted_item_id": item_id, "deleted_details_id": item_details}

Single-word bug: Missing import

    Issue: The file uses init_db from db, but there’s no explicit import statement (from db import init_db). While it’s imported inside get_items_collection, this could cause issues if init_db is not properly defined or if the import is removed accidentally.
    Fix: Add from db import init_db at the top for clarity and reliability.

Logical bug: No validation in create_item

    Issue: The create_item endpoint doesn’t validate the Item model before inserting it into the database. If the item contains invalid or missing fields, it could lead to inconsistent data in MongoDB.
    Fix: Add validation or ensure the Item model (from models) enforces required fields. For example:
    python

    if not item.name:  # Assuming 'name' is a required field
        raise HTTPException(status_code=400, detail="Item name is required")

Dependency bug: Potential MongoDB connection issue

    Issue: The get_items_collection function relies on init_db from db. If init_db fails to initialize the MongoDB connection (e.g., due to incorrect credentials or unavailable database), all endpoints will fail. There’s no error handling for this case.
    Fix: Add try-except handling in get_items_collection:
    python

        async def get_items_collection():
            try:
                from db import init_db
                return init_db()["items_collection"]
            except Exception as e:
                raise HTTPException(status_code=500, detail=f"Database connection failed: {str(e)}")

Additional Notes:

    The comment "I want a chocolate" is irrelevant and should be removed for clarity, as per your instruction to ignore comments.
    The file is not useless, as it defines core functionality for item management (CRUD operations).
    No UI/UX bugs apply, as this is a backend file.
    No explicit dependency issues beyond the MongoDB connection concern, but ensure fastapi, pymongo, and bson are in your dependencies. -->




    Number of Bugs Found and Fixed
Analysis of analytics.py for Specified Bugs
Bugs Identified (Strictly Matching Your Criteria):

    Code-breaking bug: Incorrect data access in users
        Issue: The users list is initialized with ["A1", "B2", "C3"], then appended with MongoDB documents. The code accesses user["usernames"] for all users, which raises a KeyError for "A1", "B2", "C3" (strings, not dictionaries). This breaks the code at runtime.
        Type: Code-breaking bug
        Fix: Remove the hardcoded ["A1", "B2", "C3"] to only use MongoDB documents.
    Single-word bug: Incorrect field name in user_username_lengths
        Issue: The code uses "usernames" (plural) instead of "username" (singular, likely the correct field in the User model). This causes a KeyError if the model uses "username", breaking the code.
        Type: Single-word bug
        Fix: Change "usernames" to "username".
    Single-word bug: Incorrect field name in item_name_lengths
        Issue: The code uses "names" (plural) instead of "name" (singular, likely the correct field in the Item model). This causes a KeyError if the model uses "name", breaking the code.
        Type: Single-word bug
        Fix: Change "names" to "name".
    Unnecessary code: Unused image_base64
        Issue: The histogram is generated and encoded as image_base64, but the response only returns "stats". This makes the plotting code (from plt.figure to plt.close) unnecessary, as it’s executed but not used.
        Type: Unnecessary code section
        Fix: Include image_base64 in the response to make the histogram code necessary.
<!-- Total Bugs Found in analytics.py: 7

    Incorrect data access in users: Hardcoded ["A1", "B2", "C3"] caused KeyError when accessing "username". Fixed by removing hardcoded users.
    Incorrect field name in user_username_lengths: Used "usernames" instead of "username". Fixed by changing to "username".
    Incorrect field name in item_name_lengths: Used "names" instead of "name". Fixed by changing to "name".
    Unused image_base64: Histogram was generated but not returned. Fixed by including histogram: image_base64 in the response.
    Missing dependency checks: No validation for numpy, matplotlib, etc. Not fixed in code (as it’s a project-level issue), but noted for requirements.txt.
    No error handling for empty collections: Misleading stats for empty data. Fixed by explicitly handling empty collections in stats.
    No database connection error handling: init_db failures could crash endpoints. Fixed by adding try-except in get_items_collection and get_users_collection.

Bugs Fixed in the Corrected File: 6 (all except the dependency check, which requires a separate requirements.txt update).
Additional Notes

    The histogram is now included in the response as histogram: image_base64, ensuring the plotting code is utilized.
    Ensure requirements.txt includes numpy and matplotlib to avoid runtime errors.
    If the Item or User models use different field names (not "name" or "username"), update the field names accordingly after checking models.py.

Let me know if you want me to correct another file (e.g., quiz.py or users.py) or provide further assistance! -->